<?xml version="1.0"?>
<robot name="simple_arm">

  <link name="base_link"/>

  <link name="link1"/>
  <joint name="joint1" type="revolute">
    <parent link="base_link"/>
    <child link="link1"/>
    <origin xyz="0 0 0.1"/>
    <axis xyz="0 0 1"/>
  </joint>

  <link name="end_effector"/>
  <joint name="joint2" type="fixed">
    <parent link="link1"/>
    <child link="end_effector"/>
    <origin xyz="0 0 0.2"/>
  </joint>

  <link name="camera_link"/>
  <joint name="camera_joint" type="fixed">
    <parent link="end_effector"/>
    <child link="camera_link"/>
    <origin xyz="0 0 0.05"/>
  </joint>

</robot>
